Traceback (most recent call last):
  File "C:\Users\thoma\anaconda3\envs\jupyterbook\lib\site-packages\jupyter_cache\executors\utils.py", line 58, in single_nb_execution
    executenb(
  File "C:\Users\thoma\anaconda3\envs\jupyterbook\lib\site-packages\nbclient\client.py", line 1305, in execute
    return NotebookClient(nb=nb, resources=resources, km=km, **kwargs).execute()
  File "C:\Users\thoma\anaconda3\envs\jupyterbook\lib\site-packages\jupyter_core\utils\__init__.py", line 166, in wrapped
    return loop.run_until_complete(inner)
  File "C:\Users\thoma\anaconda3\envs\jupyterbook\lib\asyncio\base_events.py", line 647, in run_until_complete
    return future.result()
  File "C:\Users\thoma\anaconda3\envs\jupyterbook\lib\site-packages\nbclient\client.py", line 705, in async_execute
    await self.async_execute_cell(
  File "C:\Users\thoma\anaconda3\envs\jupyterbook\lib\site-packages\nbclient\client.py", line 1058, in async_execute_cell
    await self._check_raise_for_error(cell, cell_index, exec_reply)
  File "C:\Users\thoma\anaconda3\envs\jupyterbook\lib\site-packages\nbclient\client.py", line 914, in _check_raise_for_error
    raise CellExecutionError.from_cell_and_msg(cell, exec_reply_content)
nbclient.exceptions.CellExecutionError: An error occurred while executing the following cell:
------------------
fig, ax = plt.subplots()
ax.plot(apypc_df.filter(regex='end').sum(axis=1), label="pending end of year")
ax.plot(apypc_anngl_anngl_anngl_anngl_anngl_df.filter(regex='Applied').sum(axis=1), label="applied during year")
ax.set_xlabel("Year")
ax.set_title("Asylum applications across all countries 2000-2017")
ax.set_ylabel("Number of asylum seekers")
ax.set_xticks([0,2,4,6,8,10,12,14,16])
ax.set_xticklabels([i for i in range(2000, 2017, 2)])
ax.set_yticklabels([i for i in range(0, 10000001, 2000000)])
ax.legend()
fig.set_size_inches(10, 5)
txt="The total number of recorded applications of asylum seekers summed over all countries between 2000 and 2017, as well as the amount of applications still pending, i.e. not processed, at the end of the year."
plt.figtext(0.5, -0.1, txt, wrap=True, horizontalalignment='center', fontsize=10)
plt.show()
------------------


[1;31m---------------------------------------------------------------------------[0m
[1;31mNameError[0m                                 Traceback (most recent call last)
Cell [1;32mIn[3], line 3[0m
[0;32m      1[0m fig, ax [38;5;241m=[39m plt[38;5;241m.[39msubplots()
[0;32m      2[0m ax[38;5;241m.[39mplot(apypc_df[38;5;241m.[39mfilter(regex[38;5;241m=[39m[38;5;124m'[39m[38;5;124mend[39m[38;5;124m'[39m)[38;5;241m.[39msum(axis[38;5;241m=[39m[38;5;241m1[39m), label[38;5;241m=[39m[38;5;124m"[39m[38;5;124mpending end of year[39m[38;5;124m"[39m)
[1;32m----> 3[0m ax[38;5;241m.[39mplot([43mapypc_anngl_anngl_anngl_anngl_anngl_df[49m[38;5;241m.[39mfilter(regex[38;5;241m=[39m[38;5;124m'[39m[38;5;124mApplied[39m[38;5;124m'[39m)[38;5;241m.[39msum(axis[38;5;241m=[39m[38;5;241m1[39m), label[38;5;241m=[39m[38;5;124m"[39m[38;5;124mapplied during year[39m[38;5;124m"[39m)
[0;32m      4[0m ax[38;5;241m.[39mset_xlabel([38;5;124m"[39m[38;5;124mYear[39m[38;5;124m"[39m)
[0;32m      5[0m ax[38;5;241m.[39mset_title([38;5;124m"[39m[38;5;124mAsylum applications across all countries 2000-2017[39m[38;5;124m"[39m)

[1;31mNameError[0m: name 'apypc_anngl_anngl_anngl_anngl_anngl_df' is not defined

